Workbook

Sheet Read Me
B2: Decommissioning Quality Health Dashboard
B3: Built from the Alpha Quality Health Dashboard slide. One dashboard per operating unit, each broken down by project, all rolling up into the Decommissioning board.
B5: Sheets
B6: Decommissioning | C6: Central board. Decommissioning totals, performance by operating unit, DNWP Lot 1 matrix (Amentum and A2R), and escalations and SOFT pulled from each unit.
B7: Alpha / Calder / Repro Decom / Windscale | C7: One dashboard per operating unit, laid out like the slide: PowerBI data (previous and current period), Quality Performance, Escalations, commentary by project, SOFT, project performance and project data entry.
B8: Settings | C8: Period number, report date and every RAG threshold. Change them once here and they apply to all dashboards.
B10: Each period
B11: 1. Settings: update the current and previous period numbers and the report date.
B12: 2. Each operating unit sheet: before typing new figures, copy the current-period PowerBI table and paste it into the previous-period table as values (Paste Special > Values). The previous-period tiles then show last period.
B13: 3. Enter the new figures in each operating unit's 'Project data entry' tables (Done and Total for each project). Live NCRs is a single count per project.
B14: 4. Add commentary by project, escalations and SOFT entries on each operating unit sheet. These appear on the Decommissioning board automatically.
B15: 5. Decommissioning sheet: set each DNWP Lot 1 measure to Red or Green for Amentum and A2R, add commentary, and add any Decommissioning-level escalations.
B17: Colour key
B18: Example | C18: Input cell. Type here.
B19: Green | C19: Green
B20: Amber | C20: Amber
B21: Red | C21: Red, or Done greater than Total in data entry
B22: N/A: no data entered | C22: N/A: no data entered, or a total of 0
B24: Example data-entry row (format only)
B25: Project | C25: CRs Done | D25: CRs Total | E25: IERs Done | F25: IERs Total | G25: …
B26: B203 | C26: 12 | D26: 15 | E26: 4 | F26: 4 | G26: …
B27: This gives CRs Sentenced on time 80.0% (12/15), Amber, and IERs 100.0% (4/4), Green. Illustrative only; the workbook ships blank.
B29: How the figures are worked out
B30: • Percentages are Done ÷ Total. Project rows add up to the operating unit total, and the operating units add up to the Decommissioning total, so a large project counts for more than a small one.
B31: • Live NCRs are added together across projects and operating units.
B32: • Percentages show one decimal place so the colour always matches the number shown (e.g. 74.7% is Red, under 75%).
B33: • RAG bands are taken from the slide legends and can be changed on the Settings sheet.
B34: • Calder, Repro Decom and Windscale project names are placeholders (Project 1–6). Type the real names in the first column of each sheet's first data-entry table. There are 8 project rows per unit.

Sheet Decommissioning
A2: Decommissioning Quality Health Dashboard | I2: =PeriodText -> Period 7 – 23/10/2026
A3: Totals are the sum of every operating unit's project figures (Done ÷ Total), not an average of percentages.
A4: PowerBI Data | J4: RAG | K4: =">"&TEXT(PBI_G,"0%") -> >90% | L4: =TEXT(PBI_R,"0%")&" – "&TEXT(PBI_G,"0%") -> 75% – 90% | M4: ="<"&TEXT(PBI_R,"0%") -> <75%
B5: CRs Sentenced on time | D5: IERs Sentenced on time | F5: Investigations approved on time | H5: LITF Completed | J5: Assurances completed on time | L5: ATLAS Actions completed on time
A6: =PrevLbl&" (previous)" -> P6 (previous) | B6: =IF(N(C77)=0,"N/A",N(B77)/C77) -> N/A | D6: =IF(N(E77)=0,"N/A",N(D77)/E77) -> N/A | F6: =IF(N(G77)=0,"N/A",N(F77)/G77) -> N/A | H6: =IF(N(I77)=0,"N/A",N(H77)/I77) -> N/A | J6: =IF(N(K77)=0,"N/A",N(J77)/K77) -> N/A | L6: =IF(N(M77)=0,"N/A",N(L77)/M77) -> N/A
B7: =IF(N(C77)=0,"",N(B77)&"/"&C77) | D7: =IF(N(E77)=0,"",N(D77)&"/"&E77) | F7: =IF(N(G77)=0,"",N(F77)&"/"&G77) | H7: =IF(N(I77)=0,"",N(H77)&"/"&I77) | J7: =IF(N(K77)=0,"",N(J77)&"/"&K77) | L7: =IF(N(M77)=0,"",N(L77)&"/"&M77)
B8: =IF(NOT(ISNUMBER(B6)),"N/A",IF(B6>PBI_G,"Green",IF(B6<PBI_R,"Red","Amber"))) -> N/A | D8: =IF(NOT(ISNUMBER(D6)),"N/A",IF(D6>PBI_G,"Green",IF(D6<PBI_R,"Red","Amber"))) -> N/A | F8: =IF(NOT(ISNUMBER(F6)),"N/A",IF(F6>PBI_G,"Green",IF(F6<PBI_R,"Red","Amber"))) -> N/A | H8: =IF(NOT(ISNUMBER(H6)),"N/A",IF(H6>PBI_G,"Green",IF(H6<PBI_R,"Red","Amber"))) -> N/A | J8: =IF(NOT(ISNUMBER(J6)),"N/A",IF(J6>PBI_G,"Green",IF(J6<PBI_R,"Red","Amber"))) -> N/A | L8: =IF(NOT(ISNUMBER(L6)),"N/A",IF(L6>PBI_G,"Green",IF(L6<PBI_R,"Red","Amber"))) -> N/A
A10: =CurLbl&" (current)" -> P7 (current) | B10: =IF(N(C68)=0,"N/A",N(B68)/C68) -> N/A | D10: =IF(N(E68)=0,"N/A",N(D68)/E68) -> N/A | F10: =IF(N(G68)=0,"N/A",N(F68)/G68) -> N/A | H10: =IF(N(I68)=0,"N/A",N(H68)/I68) -> N/A | J10: =IF(N(K68)=0,"N/A",N(J68)/K68) -> N/A | L10: =IF(N(M68)=0,"N/A",N(L68)/M68) -> N/A
B11: =IF(N(C68)=0,"",N(B68)&"/"&C68) | D11: =IF(N(E68)=0,"",N(D68)&"/"&E68) | F11: =IF(N(G68)=0,"",N(F68)&"/"&G68) | H11: =IF(N(I68)=0,"",N(H68)&"/"&I68) | J11: =IF(N(K68)=0,"",N(J68)&"/"&K68) | L11: =IF(N(M68)=0,"",N(L68)&"/"&M68)
B12: =IF(NOT(ISNUMBER(B10)),"N/A",IF(B10>PBI_G,"Green",IF(B10<PBI_R,"Red","Amber"))) -> N/A | D12: =IF(NOT(ISNUMBER(D10)),"N/A",IF(D10>PBI_G,"Green",IF(D10<PBI_R,"Red","Amber"))) -> N/A | F12: =IF(NOT(ISNUMBER(F10)),"N/A",IF(F10>PBI_G,"Green",IF(F10<PBI_R,"Red","Amber"))) -> N/A | H12: =IF(NOT(ISNUMBER(H10)),"N/A",IF(H10>PBI_G,"Green",IF(H10<PBI_R,"Red","Amber"))) -> N/A | J12: =IF(NOT(ISNUMBER(J10)),"N/A",IF(J10>PBI_G,"Green",IF(J10<PBI_R,"Red","Amber"))) -> N/A | L12: =IF(NOT(ISNUMBER(L10)),"N/A",IF(L10>PBI_G,"Green",IF(L10<PBI_R,"Red","Amber"))) -> N/A
A13: Change | B13: =IF(OR(NOT(ISNUMBER(B6)),NOT(ISNUMBER(B10))),"–",IF(ROUND(B10-B6,4)>0,"▲ ",IF(ROUND(B10-B6,4)<0,"▼ ","► "))&TEXT(ABS(B10-B6)*100,"0.0")&" pts vs "&PrevLbl) -> – | D13: =IF(OR(NOT(ISNUMBER(D6)),NOT(ISNUMBER(D10))),"–",IF(ROUND(D10-D6,4)>0,"▲ ",IF(ROUND(D10-D6,4)<0,"▼ ","► "))&TEXT(ABS(D10-D6)*100,"0.0")&" pts vs "&PrevLbl) -> – | F13: =IF(OR(NOT(ISNUMBER(F6)),NOT(ISNUMBER(F10))),"–",IF(ROUND(F10-F6,4)>0,"▲ ",IF(ROUND(F10-F6,4)<0,"▼ ","► "))&TEXT(ABS(F10-F6)*100,"0.0")&" pts vs "&PrevLbl) -> – | H13: =IF(OR(NOT(ISNUMBER(H6)),NOT(ISNUMBER(H10))),"–",IF(ROUND(H10-H6,4)>0,"▲ ",IF(ROUND(H10-H6,4)<0,"▼ ","► "))&TEXT(ABS(H10-H6)*100,"0.0")&" pts vs "&PrevLbl) -> – | J13: =IF(OR(NOT(ISNUMBER(J6)),NOT(ISNUMBER(J10))),"–",IF(ROUND(J10-J6,4)>0,"▲ ",IF(ROUND(J10-J6,4)<0,"▼ ","► "))&TEXT(ABS(J10-J6)*100,"0.0")&" pts vs "&PrevLbl) -> – | L13: =IF(OR(NOT(ISNUMBER(L6)),NOT(ISNUMBER(L10))),"–",IF(ROUND(L10-L6,4)>0,"▲ ",IF(ROUND(L10-L6,4)<0,"▼ ","► "))&TEXT(ABS(L10-L6)*100,"0.0")&" pts vs "&PrevLbl) -> –
A15: Quality Performance
B16: Non-Conformances (live NCRs) | D16: Engineering Queries | F16: Inspection Performance | H16: Lifetime Records | J16: Decommissioning escalations
B17: ="Green ≤"&NCR_G&" · Amber "&(NCR_G+1)&"–"&(NCR_R-1)&" · Red ≥"&NCR_R -> Green ≤2 · Amber 3–5 · Red ≥6 | D17: ="Green >"&TEXT(EQ_G,"0%")&" · Amber "&TEXT(EQ_R,"0%")&"–"&TEXT(EQ_G,"0%")&" · Red <"&TEXT(EQ_R,"0%") -> Green >80% · Amber 70%–80% · Red <70% | F17: ="Green >"&TEXT(INSP_G,"0%")&" · Amber "&TEXT(INSP_R,"0%")&"–"&TEXT(INSP_G,"0%")&" · Red <"&TEXT(INSP_R,"0%") -> Green >95% · Amber 90%–95% · Red <90% | H17: ="Green >"&TEXT(LTR_G,"0%")&" · Amber "&TEXT(LTR_R,"0%")&"–"&TEXT(LTR_G,"0%")&" · Red <"&TEXT(LTR_R,"0%") -> Green >95% · Amber 70%–95% · Red <70%
A18: =CurLbl&" (current)" -> P7 (current) | B18: =IF(ISNUMBER(B86),B86,"N/A") -> N/A | D18: =IF(N(E86)=0,"N/A",N(D86)/E86) -> N/A | F18: =IF(N(G86)=0,"N/A",N(F86)/G86) -> N/A | H18: =IF(N(I86)=0,"N/A",N(H86)/I86) -> N/A
B19: =IF(ISNUMBER(B86),"live NCRs","") | D19: =IF(N(E86)=0,"",N(D86)&"/"&E86) | F19: =IF(N(G86)=0,"",N(F86)&"/"&G86) | H19: =IF(N(I86)=0,"",N(H86)&"/"&I86)
B20: =IF(NOT(ISNUMBER(B18)),"N/A",IF(B18<=NCR_G,"Green",IF(B18>=NCR_R,"Red","Amber"))) -> N/A | D20: =IF(NOT(ISNUMBER(D18)),"N/A",IF(D18>EQ_G,"Green",IF(D18<EQ_R,"Red","Amber"))) -> N/A | F20: =IF(NOT(ISNUMBER(F18)),"N/A",IF(F18>INSP_G,"Green",IF(F18<INSP_R,"Red","Amber"))) -> N/A | H20: =IF(NOT(ISNUMBER(H18)),"N/A",IF(H18>LTR_G,"Green",IF(H18<LTR_R,"Red","Amber"))) -> N/A
A22: ="Performance by operating unit – current period ("&CurLbl&")" -> Performance by operating unit – current period (P7)
A23: PowerBI data
A24: Operating unit | B24: CRs Sentenced on time | D24: IERs Sentenced on time | F24: Investigations approved on time | H24: LITF Completed | J24: Assurances completed on time | L24: ATLAS Actions completed on time
A25: =HYPERLINK("#'Alpha'!A1","Alpha") -> Alpha | B25: =IF($A25="","",IF(N(C64)=0,"N/A",N(B64)/C64)) -> N/A | C25: =IF(OR($A25="",N(C64)=0),"",N(B64)&"/"&C64) | D25: =IF($A25="","",IF(N(E64)=0,"N/A",N(D64)/E64)) -> N/A | E25: =IF(OR($A25="",N(E64)=0),"",N(D64)&"/"&E64) | F25: =IF($A25="","",IF(N(G64)=0,"N/A",N(F64)/G64)) -> N/A | G25: =IF(OR($A25="",N(G64)=0),"",N(F64)&"/"&G64) | H25: =IF($A25="","",IF(N(I64)=0,"N/A",N(H64)/I64)) -> N/A | I25: =IF(OR($A25="",N(I64)=0),"",N(H64)&"/"&I64) | J25: =IF($A25="","",IF(N(K64)=0,"N/A",N(J64)/K64)) -> N/A | K25: =IF(OR($A25="",N(K64)=0),"",N(J64)&"/"&K64) | L25: =IF($A25="","",IF(N(M64)=0,"N/A",N(L64)/M64)) -> N/A | M25: =IF(OR($A25="",N(M64)=0),"",N(L64)&"/"&M64)
A26: =HYPERLINK("#'Calder'!A1","Calder") -> Calder | B26: =IF($A26="","",IF(N(C65)=0,"N/A",N(B65)/C65)) -> N/A | C26: =IF(OR($A26="",N(C65)=0),"",N(B65)&"/"&C65) | D26: =IF($A26="","",IF(N(E65)=0,"N/A",N(D65)/E65)) -> N/A | E26: =IF(OR($A26="",N(E65)=0),"",N(D65)&"/"&E65) | F26: =IF($A26="","",IF(N(G65)=0,"N/A",N(F65)/G65)) -> N/A | G26: =IF(OR($A26="",N(G65)=0),"",N(F65)&"/"&G65) | H26: =IF($A26="","",IF(N(I65)=0,"N/A",N(H65)/I65)) -> N/A | I26: =IF(OR($A26="",N(I65)=0),"",N(H65)&"/"&I65) | J26: =IF($A26="","",IF(N(K65)=0,"N/A",N(J65)/K65)) -> N/A | K26: =IF(OR($A26="",N(K65)=0),"",N(J65)&"/"&K65) | L26: =IF($A26="","",IF(N(M65)=0,"N/A",N(L65)/M65)) -> N/A | M26: =IF(OR($A26="",N(M65)=0),"",N(L65)&"/"&M65)
A27: =HYPERLINK("#'Repro Decom'!A1","Repro Decom") -> Repro Decom | B27: =IF($A27="","",IF(N(C66)=0,"N/A",N(B66)/C66)) -> N/A | C27: =IF(OR($A27="",N(C66)=0),"",N(B66)&"/"&C66) | D27: =IF($A27="","",IF(N(E66)=0,"N/A",N(D66)/E66)) -> N/A | E27: =IF(OR($A27="",N(E66)=0),"",N(D66)&"/"&E66) | F27: =IF($A27="","",IF(N(G66)=0,"N/A",N(F66)/G66)) -> N/A | G27: =IF(OR($A27="",N(G66)=0),"",N(F66)&"/"&G66) | H27: =IF($A27="","",IF(N(I66)=0,"N/A",N(H66)/I66)) -> N/A | I27: =IF(OR($A27="",N(I66)=0),"",N(H66)&"/"&I66) | J27: =IF($A27="","",IF(N(K66)=0,"N/A",N(J66)/K66)) -> N/A | K27: =IF(OR($A27="",N(K66)=0),"",N(J66)&"/"&K66) | L27: =IF($A27="","",IF(N(M66)=0,"N/A",N(L66)/M66)) -> N/A | M27: =IF(OR($A27="",N(M66)=0),"",N(L66)&"/"&M66)
A28: =HYPERLINK("#'Windscale'!A1","Windscale") -> Windscale | B28: =IF($A28="","",IF(N(C67)=0,"N/A",N(B67)/C67)) -> N/A | C28: =IF(OR($A28="",N(C67)=0),"",N(B67)&"/"&C67) | D28: =IF($A28="","",IF(N(E67)=0,"N/A",N(D67)/E67)) -> N/A | E28: =IF(OR($A28="",N(E67)=0),"",N(D67)&"/"&E67) | F28: =IF($A28="","",IF(N(G67)=0,"N/A",N(F67)/G67)) -> N/A | G28: =IF(OR($A28="",N(G67)=0),"",N(F67)&"/"&G67) | H28: =IF($A28="","",IF(N(I67)=0,"N/A",N(H67)/I67)) -> N/A | I28: =IF(OR($A28="",N(I67)=0),"",N(H67)&"/"&I67) | J28: =IF($A28="","",IF(N(K67)=0,"N/A",N(J67)/K67)) -> N/A | K28: =IF(OR($A28="",N(K67)=0),"",N(J67)&"/"&K67) | L28: =IF($A28="","",IF(N(M67)=0,"N/A",N(L67)/M67)) -> N/A | M28: =IF(OR($A28="",N(M67)=0),"",N(L67)&"/"&M67)
A29: Decommissioning total | B29: =IF($A29="","",IF(N(C68)=0,"N/A",N(B68)/C68)) -> N/A | C29: =IF(OR($A29="",N(C68)=0),"",N(B68)&"/"&C68) | D29: =IF($A29="","",IF(N(E68)=0,"N/A",N(D68)/E68)) -> N/A | E29: =IF(OR($A29="",N(E68)=0),"",N(D68)&"/"&E68) | F29: =IF($A29="","",IF(N(G68)=0,"N/A",N(F68)/G68)) -> N/A | G29: =IF(OR($A29="",N(G68)=0),"",N(F68)&"/"&G68) | H29: =IF($A29="","",IF(N(I68)=0,"N/A",N(H68)/I68)) -> N/A | I29: =IF(OR($A29="",N(I68)=0),"",N(H68)&"/"&I68) | J29: =IF($A29="","",IF(N(K68)=0,"N/A",N(J68)/K68)) -> N/A | K29: =IF(OR($A29="",N(K68)=0),"",N(J68)&"/"&K68) | L29: =IF($A29="","",IF(N(M68)=0,"N/A",N(L68)/M68)) -> N/A | M29: =IF(OR($A29="",N(M68)=0),"",N(L68)&"/"&M68)
A30: Quality Performance
A31: Operating unit | B31: Non-Conformances (live NCRs) | D31: Engineering Queries | F31: Inspection Performance | H31: Lifetime Records
A32: =HYPERLINK("#'Alpha'!A1","Alpha") -> Alpha | B32: =IF($A32="","",IF(ISNUMBER(B82),B82,"N/A")) -> N/A | D32: =IF($A32="","",IF(N(E82)=0,"N/A",N(D82)/E82)) -> N/A | E32: =IF(OR($A32="",N(E82)=0),"",N(D82)&"/"&E82) | F32: =IF($A32="","",IF(N(G82)=0,"N/A",N(F82)/G82)) -> N/A | G32: =IF(OR($A32="",N(G82)=0),"",N(F82)&"/"&G82) | H32: =IF($A32="","",IF(N(I82)=0,"N/A",N(H82)/I82)) -> N/A | I32: =IF(OR($A32="",N(I82)=0),"",N(H82)&"/"&I82)
A33: =HYPERLINK("#'Calder'!A1","Calder") -> Calder | B33: =IF($A33="","",IF(ISNUMBER(B83),B83,"N/A")) -> N/A | D33: =IF($A33="","",IF(N(E83)=0,"N/A",N(D83)/E83)) -> N/A | E33: =IF(OR($A33="",N(E83)=0),"",N(D83)&"/"&E83) | F33: =IF($A33="","",IF(N(G83)=0,"N/A",N(F83)/G83)) -> N/A | G33: =IF(OR($A33="",N(G83)=0),"",N(F83)&"/"&G83) | H33: =IF($A33="","",IF(N(I83)=0,"N/A",N(H83)/I83)) -> N/A | I33: =IF(OR($A33="",N(I83)=0),"",N(H83)&"/"&I83)
A34: =HYPERLINK("#'Repro Decom'!A1","Repro Decom") -> Repro Decom | B34: =IF($A34="","",IF(ISNUMBER(B84),B84,"N/A")) -> N/A | D34: =IF($A34="","",IF(N(E84)=0,"N/A",N(D84)/E84)) -> N/A | E34: =IF(OR($A34="",N(E84)=0),"",N(D84)&"/"&E84) | F34: =IF($A34="","",IF(N(G84)=0,"N/A",N(F84)/G84)) -> N/A | G34: =IF(OR($A34="",N(G84)=0),"",N(F84)&"/"&G84) | H34: =IF($A34="","",IF(N(I84)=0,"N/A",N(H84)/I84)) -> N/A | I34: =IF(OR($A34="",N(I84)=0),"",N(H84)&"/"&I84)
A35: =HYPERLINK("#'Windscale'!A1","Windscale") -> Windscale | B35: =IF($A35="","",IF(ISNUMBER(B85),B85,"N/A")) -> N/A | D35: =IF($A35="","",IF(N(E85)=0,"N/A",N(D85)/E85)) -> N/A | E35: =IF(OR($A35="",N(E85)=0),"",N(D85)&"/"&E85) | F35: =IF($A35="","",IF(N(G85)=0,"N/A",N(F85)/G85)) -> N/A | G35: =IF(OR($A35="",N(G85)=0),"",N(F85)&"/"&G85) | H35: =IF($A35="","",IF(N(I85)=0,"N/A",N(H85)/I85)) -> N/A | I35: =IF(OR($A35="",N(I85)=0),"",N(H85)&"/"&I85)
A36: Decommissioning total | B36: =IF($A36="","",IF(ISNUMBER(B86),B86,"N/A")) -> N/A | D36: =IF($A36="","",IF(N(E86)=0,"N/A",N(D86)/E86)) -> N/A | E36: =IF(OR($A36="",N(E86)=0),"",N(D86)&"/"&E86) | F36: =IF($A36="","",IF(N(G86)=0,"N/A",N(F86)/G86)) -> N/A | G36: =IF(OR($A36="",N(G86)=0),"",N(F86)&"/"&G86) | H36: =IF($A36="","",IF(N(I86)=0,"N/A",N(H86)/I86)) -> N/A | I36: =IF(OR($A36="",N(I86)=0),"",N(H86)&"/"&I86)
A38: ="DNWP Lot 1 performance – "&CurLbl -> DNWP Lot 1 performance – P7
A39: Choose Red or Green from the drop-down in each cell.
A40: Contracting company | B40: NCRs | D40: Supply Chain RFT | F40: NOIs | H40: Assurance Activities | J40: Assurance Actions | L40: LTR Adherence
A41: Amentum
A42: A2R
A43: Amentum commentary
A44: A2R commentary
A46: Escalations by operating unit
...

Sheet Alpha
A2: Alpha Quality Health Dashboard | I2: =PeriodText -> Period 7 – 23/10/2026
J3: =HYPERLINK("#'Alpha'!A70","Go to project data entry ▼") -> Go to project data entry ▼
A4: PowerBI Data | J4: RAG | K4: =">"&TEXT(PBI_G,"0%") -> >90% | L4: =TEXT(PBI_R,"0%")&" – "&TEXT(PBI_G,"0%") -> 75% – 90% | M4: ="<"&TEXT(PBI_R,"0%") -> <75%
B5: CRs Sentenced on time | D5: IERs Sentenced on time | F5: Investigations approved on time | H5: LITF Completed | J5: Assurances completed on time | L5: ATLAS Actions completed on time
A6: =PrevLbl&" (previous)" -> P6 (previous) | B6: =IF(N(C97)=0,"N/A",N(B97)/C97) -> N/A | D6: =IF(N(E97)=0,"N/A",N(D97)/E97) -> N/A | F6: =IF(N(G97)=0,"N/A",N(F97)/G97) -> N/A | H6: =IF(N(I97)=0,"N/A",N(H97)/I97) -> N/A | J6: =IF(N(K97)=0,"N/A",N(J97)/K97) -> N/A | L6: =IF(N(M97)=0,"N/A",N(L97)/M97) -> N/A
B7: =IF(N(C97)=0,"",N(B97)&"/"&C97) | D7: =IF(N(E97)=0,"",N(D97)&"/"&E97) | F7: =IF(N(G97)=0,"",N(F97)&"/"&G97) | H7: =IF(N(I97)=0,"",N(H97)&"/"&I97) | J7: =IF(N(K97)=0,"",N(J97)&"/"&K97) | L7: =IF(N(M97)=0,"",N(L97)&"/"&M97)
B8: =IF(NOT(ISNUMBER(B6)),"N/A",IF(B6>PBI_G,"Green",IF(B6<PBI_R,"Red","Amber"))) -> N/A | D8: =IF(NOT(ISNUMBER(D6)),"N/A",IF(D6>PBI_G,"Green",IF(D6<PBI_R,"Red","Amber"))) -> N/A | F8: =IF(NOT(ISNUMBER(F6)),"N/A",IF(F6>PBI_G,"Green",IF(F6<PBI_R,"Red","Amber"))) -> N/A | H8: =IF(NOT(ISNUMBER(H6)),"N/A",IF(H6>PBI_G,"Green",IF(H6<PBI_R,"Red","Amber"))) -> N/A | J8: =IF(NOT(ISNUMBER(J6)),"N/A",IF(J6>PBI_G,"Green",IF(J6<PBI_R,"Red","Amber"))) -> N/A | L8: =IF(NOT(ISNUMBER(L6)),"N/A",IF(L6>PBI_G,"Green",IF(L6<PBI_R,"Red","Amber"))) -> N/A
A10: =CurLbl&" (current)" -> P7 (current) | B10: =IF(N(C84)=0,"N/A",N(B84)/C84) -> N/A | D10: =IF(N(E84)=0,"N/A",N(D84)/E84) -> N/A | F10: =IF(N(G84)=0,"N/A",N(F84)/G84) -> N/A | H10: =IF(N(I84)=0,"N/A",N(H84)/I84) -> N/A | J10: =IF(N(K84)=0,"N/A",N(J84)/K84) -> N/A | L10: =IF(N(M84)=0,"N/A",N(L84)/M84) -> N/A
B11: =IF(N(C84)=0,"",N(B84)&"/"&C84) | D11: =IF(N(E84)=0,"",N(D84)&"/"&E84) | F11: =IF(N(G84)=0,"",N(F84)&"/"&G84) | H11: =IF(N(I84)=0,"",N(H84)&"/"&I84) | J11: =IF(N(K84)=0,"",N(J84)&"/"&K84) | L11: =IF(N(M84)=0,"",N(L84)&"/"&M84)
B12: =IF(NOT(ISNUMBER(B10)),"N/A",IF(B10>PBI_G,"Green",IF(B10<PBI_R,"Red","Amber"))) -> N/A | D12: =IF(NOT(ISNUMBER(D10)),"N/A",IF(D10>PBI_G,"Green",IF(D10<PBI_R,"Red","Amber"))) -> N/A | F12: =IF(NOT(ISNUMBER(F10)),"N/A",IF(F10>PBI_G,"Green",IF(F10<PBI_R,"Red","Amber"))) -> N/A | H12: =IF(NOT(ISNUMBER(H10)),"N/A",IF(H10>PBI_G,"Green",IF(H10<PBI_R,"Red","Amber"))) -> N/A | J12: =IF(NOT(ISNUMBER(J10)),"N/A",IF(J10>PBI_G,"Green",IF(J10<PBI_R,"Red","Amber"))) -> N/A | L12: =IF(NOT(ISNUMBER(L10)),"N/A",IF(L10>PBI_G,"Green",IF(L10<PBI_R,"Red","Amber"))) -> N/A
A13: Change | B13: =IF(OR(NOT(ISNUMBER(B6)),NOT(ISNUMBER(B10))),"–",IF(ROUND(B10-B6,4)>0,"▲ ",IF(ROUND(B10-B6,4)<0,"▼ ","► "))&TEXT(ABS(B10-B6)*100,"0.0")&" pts vs "&PrevLbl) -> – | D13: =IF(OR(NOT(ISNUMBER(D6)),NOT(ISNUMBER(D10))),"–",IF(ROUND(D10-D6,4)>0,"▲ ",IF(ROUND(D10-D6,4)<0,"▼ ","► "))&TEXT(ABS(D10-D6)*100,"0.0")&" pts vs "&PrevLbl) -> – | F13: =IF(OR(NOT(ISNUMBER(F6)),NOT(ISNUMBER(F10))),"–",IF(ROUND(F10-F6,4)>0,"▲ ",IF(ROUND(F10-F6,4)<0,"▼ ","► "))&TEXT(ABS(F10-F6)*100,"0.0")&" pts vs "&PrevLbl) -> – | H13: =IF(OR(NOT(ISNUMBER(H6)),NOT(ISNUMBER(H10))),"–",IF(ROUND(H10-H6,4)>0,"▲ ",IF(ROUND(H10-H6,4)<0,"▼ ","► "))&TEXT(ABS(H10-H6)*100,"0.0")&" pts vs "&PrevLbl) -> – | J13: =IF(OR(NOT(ISNUMBER(J6)),NOT(ISNUMBER(J10))),"–",IF(ROUND(J10-J6,4)>0,"▲ ",IF(ROUND(J10-J6,4)<0,"▼ ","► "))&TEXT(ABS(J10-J6)*100,"0.0")&" pts vs "&PrevLbl) -> – | L13: =IF(OR(NOT(ISNUMBER(L6)),NOT(ISNUMBER(L10))),"–",IF(ROUND(L10-L6,4)>0,"▲ ",IF(ROUND(L10-L6,4)<0,"▼ ","► "))&TEXT(ABS(L10-L6)*100,"0.0")&" pts vs "&PrevLbl) -> –
A15: Quality Performance
B16: Non-Conformances (live NCRs) | D16: Engineering Queries | F16: Inspection Performance | H16: Lifetime Records | J16: Escalations
B17: ="Green ≤"&NCR_G&" · Amber "&(NCR_G+1)&"–"&(NCR_R-1)&" · Red ≥"&NCR_R -> Green ≤2 · Amber 3–5 · Red ≥6 | D17: ="Green >"&TEXT(EQ_G,"0%")&" · Amber "&TEXT(EQ_R,"0%")&"–"&TEXT(EQ_G,"0%")&" · Red <"&TEXT(EQ_R,"0%") -> Green >80% · Amber 70%–80% · Red <70% | F17: ="Green >"&TEXT(INSP_G,"0%")&" · Amber "&TEXT(INSP_R,"0%")&"–"&TEXT(INSP_G,"0%")&" · Red <"&TEXT(INSP_R,"0%") -> Green >95% · Amber 90%–95% · Red <90% | H17: ="Green >"&TEXT(LTR_G,"0%")&" · Amber "&TEXT(LTR_R,"0%")&"–"&TEXT(LTR_G,"0%")&" · Red <"&TEXT(LTR_R,"0%") -> Green >95% · Amber 70%–95% · Red <70%
A18: =CurLbl&" (current)" -> P7 (current) | B18: =IF(ISNUMBER(B110),B110,"N/A") -> N/A | D18: =IF(N(E110)=0,"N/A",N(D110)/E110) -> N/A | F18: =IF(N(G110)=0,"N/A",N(F110)/G110) -> N/A | H18: =IF(N(I110)=0,"N/A",N(H110)/I110) -> N/A
B19: =IF(ISNUMBER(B110),"live NCRs","") | D19: =IF(N(E110)=0,"",N(D110)&"/"&E110) | F19: =IF(N(G110)=0,"",N(F110)&"/"&G110) | H19: =IF(N(I110)=0,"",N(H110)&"/"&I110)
B20: =IF(NOT(ISNUMBER(B18)),"N/A",IF(B18<=NCR_G,"Green",IF(B18>=NCR_R,"Red","Amber"))) -> N/A | D20: =IF(NOT(ISNUMBER(D18)),"N/A",IF(D18>EQ_G,"Green",IF(D18<EQ_R,"Red","Amber"))) -> N/A | F20: =IF(NOT(ISNUMBER(F18)),"N/A",IF(F18>INSP_G,"Green",IF(F18<INSP_R,"Red","Amber"))) -> N/A | H20: =IF(NOT(ISNUMBER(H18)),"N/A",IF(H18>LTR_G,"Green",IF(H18<LTR_R,"Red","Amber"))) -> N/A
A22: Quality Performance commentary by project
A23: Project | B23: Non-Conformances | D23: Engineering Queries | F23: Inspection Performance | H23: Lifetime Records
A24: Alpha (general)
A25: =IF($A$76="","",$A$76) -> B203
A26: =IF($A$77="","",$A$77) -> B277
A27: =IF($A$78="","",$A$78) -> B242
A28: =IF($A$79="","",$A$79) -> B33
A29: =IF($A$80="","",$A$80) -> B229
A30: =IF($A$81="","",$A$81) -> NGC
A31: =IF($A$82="","",$A$82)
A32: =IF($A$83="","",$A$83)
A34: SOFT – Successes, Opportunities, Failures, Threats
A35: Area | B35: Success | E35: Opportunities | H35: Failures | K35: Threats
A36: Alpha Decom Ops
A37: =IF($A$76="","",$A$76) -> B203
A38: =IF($A$77="","",$A$77) -> B277
A39: =IF($A$78="","",$A$78) -> B242
A40: =IF($A$79="","",$A$79) -> B33
A41: =IF($A$80="","",$A$80) -> B229
A42: =IF($A$81="","",$A$81) -> NGC
A43: =IF($A$82="","",$A$82)
A44: =IF($A$83="","",$A$83)
A46: ="Project performance – current period ("&CurLbl&") – calculated" -> Project performance – current period (P7) – calculated
...

Sheet Calder
A2: Calder Quality Health Dashboard | I2: =PeriodText -> Period 7 – 23/10/2026
J3: =HYPERLINK("#'Calder'!A70","Go to project data entry ▼") -> Go to project data entry ▼
A4: PowerBI Data | J4: RAG | K4: =">"&TEXT(PBI_G,"0%") -> >90% | L4: =TEXT(PBI_R,"0%")&" – "&TEXT(PBI_G,"0%") -> 75% – 90% | M4: ="<"&TEXT(PBI_R,"0%") -> <75%
B5: CRs Sentenced on time | D5: IERs Sentenced on time | F5: Investigations approved on time | H5: LITF Completed | J5: Assurances completed on time | L5: ATLAS Actions completed on time
A6: =PrevLbl&" (previous)" -> P6 (previous) | B6: =IF(N(C97)=0,"N/A",N(B97)/C97) -> N/A | D6: =IF(N(E97)=0,"N/A",N(D97)/E97) -> N/A | F6: =IF(N(G97)=0,"N/A",N(F97)/G97) -> N/A | H6: =IF(N(I97)=0,"N/A",N(H97)/I97) -> N/A | J6: =IF(N(K97)=0,"N/A",N(J97)/K97) -> N/A | L6: =IF(N(M97)=0,"N/A",N(L97)/M97) -> N/A
B7: =IF(N(C97)=0,"",N(B97)&"/"&C97) | D7: =IF(N(E97)=0,"",N(D97)&"/"&E97) | F7: =IF(N(G97)=0,"",N(F97)&"/"&G97) | H7: =IF(N(I97)=0,"",N(H97)&"/"&I97) | J7: =IF(N(K97)=0,"",N(J97)&"/"&K97) | L7: =IF(N(M97)=0,"",N(L97)&"/"&M97)
B8: =IF(NOT(ISNUMBER(B6)),"N/A",IF(B6>PBI_G,"Green",IF(B6<PBI_R,"Red","Amber"))) -> N/A | D8: =IF(NOT(ISNUMBER(D6)),"N/A",IF(D6>PBI_G,"Green",IF(D6<PBI_R,"Red","Amber"))) -> N/A | F8: =IF(NOT(ISNUMBER(F6)),"N/A",IF(F6>PBI_G,"Green",IF(F6<PBI_R,"Red","Amber"))) -> N/A | H8: =IF(NOT(ISNUMBER(H6)),"N/A",IF(H6>PBI_G,"Green",IF(H6<PBI_R,"Red","Amber"))) -> N/A | J8: =IF(NOT(ISNUMBER(J6)),"N/A",IF(J6>PBI_G,"Green",IF(J6<PBI_R,"Red","Amber"))) -> N/A | L8: =IF(NOT(ISNUMBER(L6)),"N/A",IF(L6>PBI_G,"Green",IF(L6<PBI_R,"Red","Amber"))) -> N/A
A10: =CurLbl&" (current)" -> P7 (current) | B10: =IF(N(C84)=0,"N/A",N(B84)/C84) -> N/A | D10: =IF(N(E84)=0,"N/A",N(D84)/E84) -> N/A | F10: =IF(N(G84)=0,"N/A",N(F84)/G84) -> N/A | H10: =IF(N(I84)=0,"N/A",N(H84)/I84) -> N/A | J10: =IF(N(K84)=0,"N/A",N(J84)/K84) -> N/A | L10: =IF(N(M84)=0,"N/A",N(L84)/M84) -> N/A
B11: =IF(N(C84)=0,"",N(B84)&"/"&C84) | D11: =IF(N(E84)=0,"",N(D84)&"/"&E84) | F11: =IF(N(G84)=0,"",N(F84)&"/"&G84) | H11: =IF(N(I84)=0,"",N(H84)&"/"&I84) | J11: =IF(N(K84)=0,"",N(J84)&"/"&K84) | L11: =IF(N(M84)=0,"",N(L84)&"/"&M84)
B12: =IF(NOT(ISNUMBER(B10)),"N/A",IF(B10>PBI_G,"Green",IF(B10<PBI_R,"Red","Amber"))) -> N/A | D12: =IF(NOT(ISNUMBER(D10)),"N/A",IF(D10>PBI_G,"Green",IF(D10<PBI_R,"Red","Amber"))) -> N/A | F12: =IF(NOT(ISNUMBER(F10)),"N/A",IF(F10>PBI_G,"Green",IF(F10<PBI_R,"Red","Amber"))) -> N/A | H12: =IF(NOT(ISNUMBER(H10)),"N/A",IF(H10>PBI_G,"Green",IF(H10<PBI_R,"Red","Amber"))) -> N/A | J12: =IF(NOT(ISNUMBER(J10)),"N/A",IF(J10>PBI_G,"Green",IF(J10<PBI_R,"Red","Amber"))) -> N/A | L12: =IF(NOT(ISNUMBER(L10)),"N/A",IF(L10>PBI_G,"Green",IF(L10<PBI_R,"Red","Amber"))) -> N/A
A13: Change | B13: =IF(OR(NOT(ISNUMBER(B6)),NOT(ISNUMBER(B10))),"–",IF(ROUND(B10-B6,4)>0,"▲ ",IF(ROUND(B10-B6,4)<0,"▼ ","► "))&TEXT(ABS(B10-B6)*100,"0.0")&" pts vs "&PrevLbl) -> – | D13: =IF(OR(NOT(ISNUMBER(D6)),NOT(ISNUMBER(D10))),"–",IF(ROUND(D10-D6,4)>0,"▲ ",IF(ROUND(D10-D6,4)<0,"▼ ","► "))&TEXT(ABS(D10-D6)*100,"0.0")&" pts vs "&PrevLbl) -> – | F13: =IF(OR(NOT(ISNUMBER(F6)),NOT(ISNUMBER(F10))),"–",IF(ROUND(F10-F6,4)>0,"▲ ",IF(ROUND(F10-F6,4)<0,"▼ ","► "))&TEXT(ABS(F10-F6)*100,"0.0")&" pts vs "&PrevLbl) -> – | H13: =IF(OR(NOT(ISNUMBER(H6)),NOT(ISNUMBER(H10))),"–",IF(ROUND(H10-H6,4)>0,"▲ ",IF(ROUND(H10-H6,4)<0,"▼ ","► "))&TEXT(ABS(H10-H6)*100,"0.0")&" pts vs "&PrevLbl) -> – | J13: =IF(OR(NOT(ISNUMBER(J6)),NOT(ISNUMBER(J10))),"–",IF(ROUND(J10-J6,4)>0,"▲ ",IF(ROUND(J10-J6,4)<0,"▼ ","► "))&TEXT(ABS(J10-J6)*100,"0.0")&" pts vs "&PrevLbl) -> – | L13: =IF(OR(NOT(ISNUMBER(L6)),NOT(ISNUMBER(L10))),"–",IF(ROUND(L10-L6,4)>0,"▲ ",IF(ROUND(L10-L6,4)<0,"▼ ","► "))&TEXT(ABS(L10-L6)*100,"0.0")&" pts vs "&PrevLbl) -> –
A15: Quality Performance
B16: Non-Conformances (live NCRs) | D16: Engineering Queries | F16: Inspection Performance | H16: Lifetime Records | J16: Escalations
B17: ="Green ≤"&NCR_G&" · Amber "&(NCR_G+1)&"–"&(NCR_R-1)&" · Red ≥"&NCR_R -> Green ≤2 · Amber 3–5 · Red ≥6 | D17: ="Green >"&TEXT(EQ_G,"0%")&" · Amber "&TEXT(EQ_R,"0%")&"–"&TEXT(EQ_G,"0%")&" · Red <"&TEXT(EQ_R,"0%") -> Green >80% · Amber 70%–80% · Red <70% | F17: ="Green >"&TEXT(INSP_G,"0%")&" · Amber "&TEXT(INSP_R,"0%")&"–"&TEXT(INSP_G,"0%")&" · Red <"&TEXT(INSP_R,"0%") -> Green >95% · Amber 90%–95% · Red <90% | H17: ="Green >"&TEXT(LTR_G,"0%")&" · Amber "&TEXT(LTR_R,"0%")&"–"&TEXT(LTR_G,"0%")&" · Red <"&TEXT(LTR_R,"0%") -> Green >95% · Amber 70%–95% · Red <70%
A18: =CurLbl&" (current)" -> P7 (current) | B18: =IF(ISNUMBER(B110),B110,"N/A") -> N/A | D18: =IF(N(E110)=0,"N/A",N(D110)/E110) -> N/A | F18: =IF(N(G110)=0,"N/A",N(F110)/G110) -> N/A | H18: =IF(N(I110)=0,"N/A",N(H110)/I110) -> N/A
B19: =IF(ISNUMBER(B110),"live NCRs","") | D19: =IF(N(E110)=0,"",N(D110)&"/"&E110) | F19: =IF(N(G110)=0,"",N(F110)&"/"&G110) | H19: =IF(N(I110)=0,"",N(H110)&"/"&I110)
B20: =IF(NOT(ISNUMBER(B18)),"N/A",IF(B18<=NCR_G,"Green",IF(B18>=NCR_R,"Red","Amber"))) -> N/A | D20: =IF(NOT(ISNUMBER(D18)),"N/A",IF(D18>EQ_G,"Green",IF(D18<EQ_R,"Red","Amber"))) -> N/A | F20: =IF(NOT(ISNUMBER(F18)),"N/A",IF(F18>INSP_G,"Green",IF(F18<INSP_R,"Red","Amber"))) -> N/A | H20: =IF(NOT(ISNUMBER(H18)),"N/A",IF(H18>LTR_G,"Green",IF(H18<LTR_R,"Red","Amber"))) -> N/A
A22: Quality Performance commentary by project
A23: Project | B23: Non-Conformances | D23: Engineering Queries | F23: Inspection Performance | H23: Lifetime Records
A24: Calder (general)
A25: =IF($A$76="","",$A$76) -> Project 1
A26: =IF($A$77="","",$A$77) -> Project 2
A27: =IF($A$78="","",$A$78) -> Project 3
A28: =IF($A$79="","",$A$79) -> Project 4
A29: =IF($A$80="","",$A$80) -> Project 5
A30: =IF($A$81="","",$A$81) -> Project 6
A31: =IF($A$82="","",$A$82)
A32: =IF($A$83="","",$A$83)
A34: SOFT – Successes, Opportunities, Failures, Threats
A35: Area | B35: Success | E35: Opportunities | H35: Failures | K35: Threats
A36: Calder Decom Ops
A37: =IF($A$76="","",$A$76) -> Project 1
A38: =IF($A$77="","",$A$77) -> Project 2
A39: =IF($A$78="","",$A$78) -> Project 3
A40: =IF($A$79="","",$A$79) -> Project 4
A41: =IF($A$80="","",$A$80) -> Project 5
A42: =IF($A$81="","",$A$81) -> Project 6
A43: =IF($A$82="","",$A$82)
A44: =IF($A$83="","",$A$83)
A46: ="Project performance – current period ("&CurLbl&") – calculated" -> Project performance – current period (P7) – calculated
...

Sheet Repro Decom
A2: Repro Decom Quality Health Dashboard | I2: =PeriodText -> Period 7 – 23/10/2026
J3: =HYPERLINK("#'Repro Decom'!A70","Go to project data entry ▼") -> Go to project data entry ▼
A4: PowerBI Data | J4: RAG | K4: =">"&TEXT(PBI_G,"0%") -> >90% | L4: =TEXT(PBI_R,"0%")&" – "&TEXT(PBI_G,"0%") -> 75% – 90% | M4: ="<"&TEXT(PBI_R,"0%") -> <75%
B5: CRs Sentenced on time | D5: IERs Sentenced on time | F5: Investigations approved on time | H5: LITF Completed | J5: Assurances completed on time | L5: ATLAS Actions completed on time
A6: =PrevLbl&" (previous)" -> P6 (previous) | B6: =IF(N(C97)=0,"N/A",N(B97)/C97) -> N/A | D6: =IF(N(E97)=0,"N/A",N(D97)/E97) -> N/A | F6: =IF(N(G97)=0,"N/A",N(F97)/G97) -> N/A | H6: =IF(N(I97)=0,"N/A",N(H97)/I97) -> N/A | J6: =IF(N(K97)=0,"N/A",N(J97)/K97) -> N/A | L6: =IF(N(M97)=0,"N/A",N(L97)/M97) -> N/A
B7: =IF(N(C97)=0,"",N(B97)&"/"&C97) | D7: =IF(N(E97)=0,"",N(D97)&"/"&E97) | F7: =IF(N(G97)=0,"",N(F97)&"/"&G97) | H7: =IF(N(I97)=0,"",N(H97)&"/"&I97) | J7: =IF(N(K97)=0,"",N(J97)&"/"&K97) | L7: =IF(N(M97)=0,"",N(L97)&"/"&M97)
B8: =IF(NOT(ISNUMBER(B6)),"N/A",IF(B6>PBI_G,"Green",IF(B6<PBI_R,"Red","Amber"))) -> N/A | D8: =IF(NOT(ISNUMBER(D6)),"N/A",IF(D6>PBI_G,"Green",IF(D6<PBI_R,"Red","Amber"))) -> N/A | F8: =IF(NOT(ISNUMBER(F6)),"N/A",IF(F6>PBI_G,"Green",IF(F6<PBI_R,"Red","Amber"))) -> N/A | H8: =IF(NOT(ISNUMBER(H6)),"N/A",IF(H6>PBI_G,"Green",IF(H6<PBI_R,"Red","Amber"))) -> N/A | J8: =IF(NOT(ISNUMBER(J6)),"N/A",IF(J6>PBI_G,"Green",IF(J6<PBI_R,"Red","Amber"))) -> N/A | L8: =IF(NOT(ISNUMBER(L6)),"N/A",IF(L6>PBI_G,"Green",IF(L6<PBI_R,"Red","Amber"))) -> N/A
A10: =CurLbl&" (current)" -> P7 (current) | B10: =IF(N(C84)=0,"N/A",N(B84)/C84) -> N/A | D10: =IF(N(E84)=0,"N/A",N(D84)/E84) -> N/A | F10: =IF(N(G84)=0,"N/A",N(F84)/G84) -> N/A | H10: =IF(N(I84)=0,"N/A",N(H84)/I84) -> N/A | J10: =IF(N(K84)=0,"N/A",N(J84)/K84) -> N/A | L10: =IF(N(M84)=0,"N/A",N(L84)/M84) -> N/A
B11: =IF(N(C84)=0,"",N(B84)&"/"&C84) | D11: =IF(N(E84)=0,"",N(D84)&"/"&E84) | F11: =IF(N(G84)=0,"",N(F84)&"/"&G84) | H11: =IF(N(I84)=0,"",N(H84)&"/"&I84) | J11: =IF(N(K84)=0,"",N(J84)&"/"&K84) | L11: =IF(N(M84)=0,"",N(L84)&"/"&M84)
B12: =IF(NOT(ISNUMBER(B10)),"N/A",IF(B10>PBI_G,"Green",IF(B10<PBI_R,"Red","Amber"))) -> N/A | D12: =IF(NOT(ISNUMBER(D10)),"N/A",IF(D10>PBI_G,"Green",IF(D10<PBI_R,"Red","Amber"))) -> N/A | F12: =IF(NOT(ISNUMBER(F10)),"N/A",IF(F10>PBI_G,"Green",IF(F10<PBI_R,"Red","Amber"))) -> N/A | H12: =IF(NOT(ISNUMBER(H10)),"N/A",IF(H10>PBI_G,"Green",IF(H10<PBI_R,"Red","Amber"))) -> N/A | J12: =IF(NOT(ISNUMBER(J10)),"N/A",IF(J10>PBI_G,"Green",IF(J10<PBI_R,"Red","Amber"))) -> N/A | L12: =IF(NOT(ISNUMBER(L10)),"N/A",IF(L10>PBI_G,"Green",IF(L10<PBI_R,"Red","Amber"))) -> N/A
A13: Change | B13: =IF(OR(NOT(ISNUMBER(B6)),NOT(ISNUMBER(B10))),"–",IF(ROUND(B10-B6,4)>0,"▲ ",IF(ROUND(B10-B6,4)<0,"▼ ","► "))&TEXT(ABS(B10-B6)*100,"0.0")&" pts vs "&PrevLbl) -> – | D13: =IF(OR(NOT(ISNUMBER(D6)),NOT(ISNUMBER(D10))),"–",IF(ROUND(D10-D6,4)>0,"▲ ",IF(ROUND(D10-D6,4)<0,"▼ ","► "))&TEXT(ABS(D10-D6)*100,"0.0")&" pts vs "&PrevLbl) -> – | F13: =IF(OR(NOT(ISNUMBER(F6)),NOT(ISNUMBER(F10))),"–",IF(ROUND(F10-F6,4)>0,"▲ ",IF(ROUND(F10-F6,4)<0,"▼ ","► "))&TEXT(ABS(F10-F6)*100,"0.0")&" pts vs "&PrevLbl) -> – | H13: =IF(OR(NOT(ISNUMBER(H6)),NOT(ISNUMBER(H10))),"–",IF(ROUND(H10-H6,4)>0,"▲ ",IF(ROUND(H10-H6,4)<0,"▼ ","► "))&TEXT(ABS(H10-H6)*100,"0.0")&" pts vs "&PrevLbl) -> – | J13: =IF(OR(NOT(ISNUMBER(J6)),NOT(ISNUMBER(J10))),"–",IF(ROUND(J10-J6,4)>0,"▲ ",IF(ROUND(J10-J6,4)<0,"▼ ","► "))&TEXT(ABS(J10-J6)*100,"0.0")&" pts vs "&PrevLbl) -> – | L13: =IF(OR(NOT(ISNUMBER(L6)),NOT(ISNUMBER(L10))),"–",IF(ROUND(L10-L6,4)>0,"▲ ",IF(ROUND(L10-L6,4)<0,"▼ ","► "))&TEXT(ABS(L10-L6)*100,"0.0")&" pts vs "&PrevLbl) -> –
A15: Quality Performance
B16: Non-Conformances (live NCRs) | D16: Engineering Queries | F16: Inspection Performance | H16: Lifetime Records | J16: Escalations
B17: ="Green ≤"&NCR_G&" · Amber "&(NCR_G+1)&"–"&(NCR_R-1)&" · Red ≥"&NCR_R -> Green ≤2 · Amber 3–5 · Red ≥6 | D17: ="Green >"&TEXT(EQ_G,"0%")&" · Amber "&TEXT(EQ_R,"0%")&"–"&TEXT(EQ_G,"0%")&" · Red <"&TEXT(EQ_R,"0%") -> Green >80% · Amber 70%–80% · Red <70% | F17: ="Green >"&TEXT(INSP_G,"0%")&" · Amber "&TEXT(INSP_R,"0%")&"–"&TEXT(INSP_G,"0%")&" · Red <"&TEXT(INSP_R,"0%") -> Green >95% · Amber 90%–95% · Red <90% | H17: ="Green >"&TEXT(LTR_G,"0%")&" · Amber "&TEXT(LTR_R,"0%")&"–"&TEXT(LTR_G,"0%")&" · Red <"&TEXT(LTR_R,"0%") -> Green >95% · Amber 70%–95% · Red <70%
A18: =CurLbl&" (current)" -> P7 (current) | B18: =IF(ISNUMBER(B110),B110,"N/A") -> N/A | D18: =IF(N(E110)=0,"N/A",N(D110)/E110) -> N/A | F18: =IF(N(G110)=0,"N/A",N(F110)/G110) -> N/A | H18: =IF(N(I110)=0,"N/A",N(H110)/I110) -> N/A
B19: =IF(ISNUMBER(B110),"live NCRs","") | D19: =IF(N(E110)=0,"",N(D110)&"/"&E110) | F19: =IF(N(G110)=0,"",N(F110)&"/"&G110) | H19: =IF(N(I110)=0,"",N(H110)&"/"&I110)
B20: =IF(NOT(ISNUMBER(B18)),"N/A",IF(B18<=NCR_G,"Green",IF(B18>=NCR_R,"Red","Amber"))) -> N/A | D20: =IF(NOT(ISNUMBER(D18)),"N/A",IF(D18>EQ_G,"Green",IF(D18<EQ_R,"Red","Amber"))) -> N/A | F20: =IF(NOT(ISNUMBER(F18)),"N/A",IF(F18>INSP_G,"Green",IF(F18<INSP_R,"Red","Amber"))) -> N/A | H20: =IF(NOT(ISNUMBER(H18)),"N/A",IF(H18>LTR_G,"Green",IF(H18<LTR_R,"Red","Amber"))) -> N/A
A22: Quality Performance commentary by project
A23: Project | B23: Non-Conformances | D23: Engineering Queries | F23: Inspection Performance | H23: Lifetime Records
A24: Repro Decom (general)
A25: =IF($A$76="","",$A$76) -> Project 1
A26: =IF($A$77="","",$A$77) -> Project 2
A27: =IF($A$78="","",$A$78) -> Project 3
A28: =IF($A$79="","",$A$79) -> Project 4
A29: =IF($A$80="","",$A$80) -> Project 5
A30: =IF($A$81="","",$A$81) -> Project 6
A31: =IF($A$82="","",$A$82)
A32: =IF($A$83="","",$A$83)
A34: SOFT – Successes, Opportunities, Failures, Threats
A35: Area | B35: Success | E35: Opportunities | H35: Failures | K35: Threats
A36: Repro Decom Decom Ops
A37: =IF($A$76="","",$A$76) -> Project 1
A38: =IF($A$77="","",$A$77) -> Project 2
A39: =IF($A$78="","",$A$78) -> Project 3
A40: =IF($A$79="","",$A$79) -> Project 4
A41: =IF($A$80="","",$A$80) -> Project 5
A42: =IF($A$81="","",$A$81) -> Project 6
A43: =IF($A$82="","",$A$82)
A44: =IF($A$83="","",$A$83)
A46: ="Project performance – current period ("&CurLbl&") – calculated" -> Project performance – current period (P7) – calculated
...

Sheet Windscale
A2: Windscale Quality Health Dashboard | I2: =PeriodText -> Period 7 – 23/10/2026
J3: =HYPERLINK("#'Windscale'!A70","Go to project data entry ▼") -> Go to project data entry ▼
A4: PowerBI Data | J4: RAG | K4: =">"&TEXT(PBI_G,"0%") -> >90% | L4: =TEXT(PBI_R,"0%")&" – "&TEXT(PBI_G,"0%") -> 75% – 90% | M4: ="<"&TEXT(PBI_R,"0%") -> <75%
B5: CRs Sentenced on time | D5: IERs Sentenced on time | F5: Investigations approved on time | H5: LITF Completed | J5: Assurances completed on time | L5: ATLAS Actions completed on time
A6: =PrevLbl&" (previous)" -> P6 (previous) | B6: =IF(N(C97)=0,"N/A",N(B97)/C97) -> N/A | D6: =IF(N(E97)=0,"N/A",N(D97)/E97) -> N/A | F6: =IF(N(G97)=0,"N/A",N(F97)/G97) -> N/A | H6: =IF(N(I97)=0,"N/A",N(H97)/I97) -> N/A | J6: =IF(N(K97)=0,"N/A",N(J97)/K97) -> N/A | L6: =IF(N(M97)=0,"N/A",N(L97)/M97) -> N/A
B7: =IF(N(C97)=0,"",N(B97)&"/"&C97) | D7: =IF(N(E97)=0,"",N(D97)&"/"&E97) | F7: =IF(N(G97)=0,"",N(F97)&"/"&G97) | H7: =IF(N(I97)=0,"",N(H97)&"/"&I97) | J7: =IF(N(K97)=0,"",N(J97)&"/"&K97) | L7: =IF(N(M97)=0,"",N(L97)&"/"&M97)
B8: =IF(NOT(ISNUMBER(B6)),"N/A",IF(B6>PBI_G,"Green",IF(B6<PBI_R,"Red","Amber"))) -> N/A | D8: =IF(NOT(ISNUMBER(D6)),"N/A",IF(D6>PBI_G,"Green",IF(D6<PBI_R,"Red","Amber"))) -> N/A | F8: =IF(NOT(ISNUMBER(F6)),"N/A",IF(F6>PBI_G,"Green",IF(F6<PBI_R,"Red","Amber"))) -> N/A | H8: =IF(NOT(ISNUMBER(H6)),"N/A",IF(H6>PBI_G,"Green",IF(H6<PBI_R,"Red","Amber"))) -> N/A | J8: =IF(NOT(ISNUMBER(J6)),"N/A",IF(J6>PBI_G,"Green",IF(J6<PBI_R,"Red","Amber"))) -> N/A | L8: =IF(NOT(ISNUMBER(L6)),"N/A",IF(L6>PBI_G,"Green",IF(L6<PBI_R,"Red","Amber"))) -> N/A
A10: =CurLbl&" (current)" -> P7 (current) | B10: =IF(N(C84)=0,"N/A",N(B84)/C84) -> N/A | D10: =IF(N(E84)=0,"N/A",N(D84)/E84) -> N/A | F10: =IF(N(G84)=0,"N/A",N(F84)/G84) -> N/A | H10: =IF(N(I84)=0,"N/A",N(H84)/I84) -> N/A | J10: =IF(N(K84)=0,"N/A",N(J84)/K84) -> N/A | L10: =IF(N(M84)=0,"N/A",N(L84)/M84) -> N/A
B11: =IF(N(C84)=0,"",N(B84)&"/"&C84) | D11: =IF(N(E84)=0,"",N(D84)&"/"&E84) | F11: =IF(N(G84)=0,"",N(F84)&"/"&G84) | H11: =IF(N(I84)=0,"",N(H84)&"/"&I84) | J11: =IF(N(K84)=0,"",N(J84)&"/"&K84) | L11: =IF(N(M84)=0,"",N(L84)&"/"&M84)
B12: =IF(NOT(ISNUMBER(B10)),"N/A",IF(B10>PBI_G,"Green",IF(B10<PBI_R,"Red","Amber"))) -> N/A | D12: =IF(NOT(ISNUMBER(D10)),"N/A",IF(D10>PBI_G,"Green",IF(D10<PBI_R,"Red","Amber"))) -> N/A | F12: =IF(NOT(ISNUMBER(F10)),"N/A",IF(F10>PBI_G,"Green",IF(F10<PBI_R,"Red","Amber"))) -> N/A | H12: =IF(NOT(ISNUMBER(H10)),"N/A",IF(H10>PBI_G,"Green",IF(H10<PBI_R,"Red","Amber"))) -> N/A | J12: =IF(NOT(ISNUMBER(J10)),"N/A",IF(J10>PBI_G,"Green",IF(J10<PBI_R,"Red","Amber"))) -> N/A | L12: =IF(NOT(ISNUMBER(L10)),"N/A",IF(L10>PBI_G,"Green",IF(L10<PBI_R,"Red","Amber"))) -> N/A
A13: Change | B13: =IF(OR(NOT(ISNUMBER(B6)),NOT(ISNUMBER(B10))),"–",IF(ROUND(B10-B6,4)>0,"▲ ",IF(ROUND(B10-B6,4)<0,"▼ ","► "))&TEXT(ABS(B10-B6)*100,"0.0")&" pts vs "&PrevLbl) -> – | D13: =IF(OR(NOT(ISNUMBER(D6)),NOT(ISNUMBER(D10))),"–",IF(ROUND(D10-D6,4)>0,"▲ ",IF(ROUND(D10-D6,4)<0,"▼ ","► "))&TEXT(ABS(D10-D6)*100,"0.0")&" pts vs "&PrevLbl) -> – | F13: =IF(OR(NOT(ISNUMBER(F6)),NOT(ISNUMBER(F10))),"–",IF(ROUND(F10-F6,4)>0,"▲ ",IF(ROUND(F10-F6,4)<0,"▼ ","► "))&TEXT(ABS(F10-F6)*100,"0.0")&" pts vs "&PrevLbl) -> – | H13: =IF(OR(NOT(ISNUMBER(H6)),NOT(ISNUMBER(H10))),"–",IF(ROUND(H10-H6,4)>0,"▲ ",IF(ROUND(H10-H6,4)<0,"▼ ","► "))&TEXT(ABS(H10-H6)*100,"0.0")&" pts vs "&PrevLbl) -> – | J13: =IF(OR(NOT(ISNUMBER(J6)),NOT(ISNUMBER(J10))),"–",IF(ROUND(J10-J6,4)>0,"▲ ",IF(ROUND(J10-J6,4)<0,"▼ ","► "))&TEXT(ABS(J10-J6)*100,"0.0")&" pts vs "&PrevLbl) -> – | L13: =IF(OR(NOT(ISNUMBER(L6)),NOT(ISNUMBER(L10))),"–",IF(ROUND(L10-L6,4)>0,"▲ ",IF(ROUND(L10-L6,4)<0,"▼ ","► "))&TEXT(ABS(L10-L6)*100,"0.0")&" pts vs "&PrevLbl) -> –
A15: Quality Performance
B16: Non-Conformances (live NCRs) | D16: Engineering Queries | F16: Inspection Performance | H16: Lifetime Records | J16: Escalations
B17: ="Green ≤"&NCR_G&" · Amber "&(NCR_G+1)&"–"&(NCR_R-1)&" · Red ≥"&NCR_R -> Green ≤2 · Amber 3–5 · Red ≥6 | D17: ="Green >"&TEXT(EQ_G,"0%")&" · Amber "&TEXT(EQ_R,"0%")&"–"&TEXT(EQ_G,"0%")&" · Red <"&TEXT(EQ_R,"0%") -> Green >80% · Amber 70%–80% · Red <70% | F17: ="Green >"&TEXT(INSP_G,"0%")&" · Amber "&TEXT(INSP_R,"0%")&"–"&TEXT(INSP_G,"0%")&" · Red <"&TEXT(INSP_R,"0%") -> Green >95% · Amber 90%–95% · Red <90% | H17: ="Green >"&TEXT(LTR_G,"0%")&" · Amber "&TEXT(LTR_R,"0%")&"–"&TEXT(LTR_G,"0%")&" · Red <"&TEXT(LTR_R,"0%") -> Green >95% · Amber 70%–95% · Red <70%
A18: =CurLbl&" (current)" -> P7 (current) | B18: =IF(ISNUMBER(B110),B110,"N/A") -> N/A | D18: =IF(N(E110)=0,"N/A",N(D110)/E110) -> N/A | F18: =IF(N(G110)=0,"N/A",N(F110)/G110) -> N/A | H18: =IF(N(I110)=0,"N/A",N(H110)/I110) -> N/A
B19: =IF(ISNUMBER(B110),"live NCRs","") | D19: =IF(N(E110)=0,"",N(D110)&"/"&E110) | F19: =IF(N(G110)=0,"",N(F110)&"/"&G110) | H19: =IF(N(I110)=0,"",N(H110)&"/"&I110)
B20: =IF(NOT(ISNUMBER(B18)),"N/A",IF(B18<=NCR_G,"Green",IF(B18>=NCR_R,"Red","Amber"))) -> N/A | D20: =IF(NOT(ISNUMBER(D18)),"N/A",IF(D18>EQ_G,"Green",IF(D18<EQ_R,"Red","Amber"))) -> N/A | F20: =IF(NOT(ISNUMBER(F18)),"N/A",IF(F18>INSP_G,"Green",IF(F18<INSP_R,"Red","Amber"))) -> N/A | H20: =IF(NOT(ISNUMBER(H18)),"N/A",IF(H18>LTR_G,"Green",IF(H18<LTR_R,"Red","Amber"))) -> N/A
A22: Quality Performance commentary by project
A23: Project | B23: Non-Conformances | D23: Engineering Queries | F23: Inspection Performance | H23: Lifetime Records
A24: Windscale (general)
A25: =IF($A$76="","",$A$76) -> Project 1
A26: =IF($A$77="","",$A$77) -> Project 2
A27: =IF($A$78="","",$A$78) -> Project 3
A28: =IF($A$79="","",$A$79) -> Project 4
A29: =IF($A$80="","",$A$80) -> Project 5
A30: =IF($A$81="","",$A$81) -> Project 6
A31: =IF($A$82="","",$A$82)
A32: =IF($A$83="","",$A$83)
A34: SOFT – Successes, Opportunities, Failures, Threats
A35: Area | B35: Success | E35: Opportunities | H35: Failures | K35: Threats
A36: Windscale Decom Ops
A37: =IF($A$76="","",$A$76) -> Project 1
A38: =IF($A$77="","",$A$77) -> Project 2
A39: =IF($A$78="","",$A$78) -> Project 3
A40: =IF($A$79="","",$A$79) -> Project 4
A41: =IF($A$80="","",$A$80) -> Project 5
A42: =IF($A$81="","",$A$81) -> Project 6
A43: =IF($A$82="","",$A$82)
A44: =IF($A$83="","",$A$83)
A46: ="Project performance – current period ("&CurLbl&") – calculated" -> Project performance – current period (P7) – calculated
...

Sheet Settings
A2: Settings
A3: Pale yellow cells are inputs. Everything else is calculated.
A4: Reporting period
A5: Current period number | B5: 7 | E5: From the source slide: “Period 7 – 23/10/2026”.
A6: Previous period number | B6: 6
A7: Report date | B7: 46318
A8: Current period label | B8: ="P"&B5 -> P7
A9: Previous period label | B9: ="P"&B6 -> P6
A10: Dashboard heading | B10: ="Period "&B5&" – "&TEXT(B7,"dd/mm/yyyy") -> Period 7 – 23/10/2026
A12: RAG thresholds
A13: Measure | B13: Applies to | C13: Green when | D13: Red when | E13: Notes
A14: PowerBI KPIs | B14: CRs, IERs, Investigations, LITF, Assurances, ATLAS Actions | C14: 0.9 | D14: 0.75 | E14: Slide legend: >90% / 75%–90% / <75%. Green is strictly above, Red strictly below; anything between is Amber.
A15: Non-Conformances | B15: Live NCR count (lower is better) | C15: 2 | D15: 6 | E15: Slide legend: 1 to 2 / 3–5 / 6+. Green when at or below; Red when at or above. 0 live NCRs is Green.
A16: Engineering Queries | B16: % closed on time | C16: 0.8 | D16: 0.7 | E16: Slide legend: >80% / 70%–80% / <70%.
A17: Inspection Performance | B17: % completed | C17: 0.95 | D17: 0.9 | E17: Slide legend: >95% / 90%–94% / <90%. Exactly 95% is treated as Amber.
A18: Lifetime Records | B18: % compliant | C18: 0.95 | D18: 0.7 | E18: Slide legend: >95% / 70%–95% / <70%.
